Workbook

Sheet BD Strategy v2
A1: Singapore Headhunting BD Target List v2 — Data Eng · AI Governance · AI Security · AI Risk · Software Eng
A2: Expanded Oct 2026 from v1 (original sheets kept at the back unchanged). Company-level research from public sources; no personal data scraped.
A4: What changed in v2
A5: • Master list now covers 222 accounts (v1: 60 kept/merged, v2: 79 new, v2.1: 83 added by splitting grouped rows into individual companies), all in one filterable sheet with role flags for 5 directions.
A6: • v2.1: every grouped row (e.g. 'Chinese credit-tech going abroad', Chinese bank branches, quant funds, wallets, robotics, handset makers, IT vendors, MindForge members, public sector) is now one row per company. Each split row says which group it came from in 'v2 Update / Correction'. New finds: Lingjun (灵均) SG office, SUNRATE, TrustDecision (同盾), OneConnect (金融壹账通), Kuaishou's SG unit, PixVerse, China Life SG, DCITS, Sunline, XTransfer's MAS licence.
A7: • Wider definition of 'Chinese-connected' (China Link A–E): not only Chinese-HQ firms, but SG-relocated Chinese startups, Greater-China/diaspora founders, and non-Chinese firms with China-origin tech leaders or TA (type D — verify on LinkedIn).
A8: • Added AI Security and AI Risk as directions, plus general Software Engineering. Companies are included if a need is plausible, not only if a role is posted today.
A9: • Corrections to v1: PingPong ≠ 连连数字 (LianLian is a separate company, added); Binance has no MAS licence and exited SG retail in 2021 (verify roles); Haitong International merged into Guotai Haitong; MiniMax and Zhipu upgraded — SG entities now confirmed.
A11: Why now — new signals since v1
A12: 1. Chinese AI companies keep moving to SG ('Singapore-washing'): Manus (→ Meta), MiroMind/Shanda (AGI research exclusively in SG from Jan 2026), Tabcut, Plaud (APAC HQ opened 16 Sep 2026, 100→150 staff). Beijing is now scrutinising these moves (Manus deal review) — relocating teams face backfill gaps for staff who won't move.
A13: 2. MAS AI Risk Management Guidelines (7 Oct 2026) apply to ALL regulated FIs — including Chinese bank branches, Chinese online brokers (Moomoo/Futu, Tiger), digital banks (ANEXT, Green Link, MariBank, GXS) and crypto/payment licensees. Their China HQs often don't know the requirement → you can bring both the regulation insight and the talent.
A14: 3. Chinese giants are running an AI-talent war in SG (campus recruiting at NUS/NTU by Huawei, Alibaba, ByteDance, Trip.com, MiniMax in 2026) — lateral hiring budgets follow.
... A32: Public sources incl. MAS (7 Oct 2026), EDB (Plaud, Sep 2026), SCMP (MiroMind Jan 2026; Manus 2025), Bloomberg (ByteDance Seed Feb 2026; WeRide/Pony Sep 2025), e27 (OneByZero Oct 2026), KrASIA (Ropedia), HCAmag/People Matters (campus AI hiring 2026), company sites and filings. Founder backgrounds for some startups are marked 'verify' — do not rely on names alone; confirm on LinkedIn. All signals are a snapshot as of 8 Oct 2026.

Sheet LinkedIn Setup Guide
A1: LinkedIn Recruiter setup — step by step
A3: 1. PROJECTS
A4: Create 3 projects | B4: 'BD-W1 High' (40 companies) · 'BD-W2 Medium' (93) · 'BD-W3 Long-tail' (71). Project = column E in 'LinkedIn Search Plan'. Mark them as BD / client development (not a job) so they don't mix with candidate pipelines.
A5: Pipeline stages | B5: Rename the stages to: Uncontacted → InMail sent → Replied → Meeting → Proposal / terms → Client (signed) → Not now.
A6: Tags | B6: Create tags so you can filter across projects: Persona (HM / TA / Founder), Direction (DE / AIGov / AISec / AIRisk / SWE), China Link (A-E), Lang (CN / EN).
A7: 2. FIND PEOPLE
A8: Per company | B8: Search → Current company = column C (pick the exact company page in the dropdown) + Location = Singapore. Paste column F into Job titles (Boolean) for hiring managers, then repeat with column G for TA/HR (and column H for startup founders).
A9: Who to save (2-4 per company) | B9: 1 hiring manager in your direction (Head of Data / AI governance / security / risk / Eng), 1 senior leader (CTO / CRO / CDO), 1 TA/HR contact. For startups (<50 staff), the founder or CTO alone is enough.
A10: Spotlights for Chinese-speaking contacts | B10: In Recruiter's spotlight / filters: Spoken languages = Chinese; Schools = Tsinghua, Peking, Zhejiang, SJTU, Fudan, USTC; Past company = ByteDance, Alibaba, Tencent, Huawei. Use these to choose the CN or EN template.
A11: Before saving | B11: For rows marked [verify SG team first], check the company page and its SG job posts. If it has no SG staff, mark the row Dead and skip it.
A12: 3. MESSAGING
A13: Save the templates | B13: Create each template in the 'InMail Templates' sheet in Recruiter, then swap {firstName} / {company} / {senderFirstName} for Recruiter's Insert variables.
A14: Pick the template | B14: Column J = suggested first message. Use the T6 (TA/HR) template for TA/HR contacts. Always rewrite the [signal] line using the 'BD Signal / Why Now' column of the Master list.
A15: Cadence | B15: Day 0 InMail → day 5-7 F1 (with a data point or anonymised profile) → day 14 F2 (close the loop). Message no more than 2 people per company in the same week.
A16: InMail budget | B16: About 120 InMails for Wave 1 (3 people × 40 companies). Recruiter Lite has far fewer monthly credits than Recruiter Corporate, so check your seat. Save InMails for hiring managers, and use connection requests with a note (≤300 characters) or free messages to Open Profiles for the rest.
A17: Track | B17: Update 'LinkedIn Search Plan' columns L-N and the Master list's BD Status; the Summary sheet counts the pipeline automatically.
A18: 4. COMPLIANCE
A19: Data | B19: Keep contact details inside LinkedIn and your own ATS/CRM. Don't export profiles in bulk; respect LinkedIn's terms and Singapore's PDPA.

Sheet Master Target List
A1: Master BD Target List (Singapore) — Data Eng · AI Governance · AI Security · AI Risk · Software Eng
A2: China Link: A = Chinese HQ/SOE · B = Chinese-founded, HQ'd/relocated to SG · C = Greater-China / Chinese-diaspora founders · D = non-Chinese firm with China-origin tech leaders/TA (verify) · E = role fit only. Role columns: ● = core need, ○ = likely/possible. Yellow columns (BD Status, Next Step) are yours to fill in.
A4: # | B4: Company | C4: Chinese Name | D4: Category | E4: China Link | F4: China Link Detail | G4: Data Eng | H4: AI Gov | I4: AI Security | J4: AI Risk | K4: SWE | L4: Size / Stage | M4: BD Signal / Why Now | N4: Suggested BD Angle | O4: Priority | P4: Confidence | Q4: Source | R4: Origin | S4: v2 Update / Correction | T4: BD Status | U4: Next Step / Notes
A5: 1 | B5: Plaud | C5: Plaud.ai | D5: AI Startups & Labs (Chinese-founded / SG-relocated) | E5: B | F5: Chinese-founded AI hardware/agent company; Singapore is its APAC HQ and first R&D hub outside HQ | G5: ● | H5: ○ | K5: ● | L5: Scale-up; SG team ~10 → ~100 in 9 months, target 150 | M5: Opened 15,000 sq ft APAC HQ at MBFC on 16 Sep 2026; doubled SG investment to ≥S$20M; actively hiring AI engineers, AI agent architects, data scientists for its first overseas R&D hub | N5: Hottest Chinese-founded AI hiring signal in SG right now — team is 2/3 of the way to its 150 target, TA is stretched; pitch AI/agent engineers + data scientists, Mandarin-speaking HQ liaison | O5: High | P5: Confirmed | Q5: EDB press release (Sep 2026); HRO / TechCoffeeHouse Jun & Sep 2026 | R5: v2 new | T5: Not started
A6: 2 | B6: MiroMind (Shanda Group) | C6: 盛大 MiroMind | D6: AI Startups & Labs (Chinese-founded / SG-relocated) | E6: B | F6: Backed by Shanda (Chen Tianqiao); Jan 2026 reorg made Singapore the exclusive base for its AGI research; Shanghai staff asked to relocate | G6: ○ | I6: ● | K6: ● | L6: Research lab; >80% PhD team (per public posts) | M6: Jan 2026: AGI / fundamental research to be done exclusively in Singapore; careers page hiring engineers for a SG-based team; a 'Verifiable AI Lab' is being set up | N6: Relocation = backfill gap for staff who won't move from Shanghai; pitch research engineers, LLM infra, and AI safety / verification profiles | O6: High | P6: Confirmed | Q6: SCMP Jan 2026; miromind.ai careers / announcement | R6: v2 new | T6: Not started
A7: 3 | B7: Ropedia | C7: Ropedia | D7: AI Startups & Labs (Chinese-founded / SG-relocated) | E7: C | F7: SG-based physical-AI data infrastructure; co-founders Zhaoxi Chen & Fangzhou Hong (verify background on LinkedIn) | G7: ● | K7: ● | L7: Pre-Series A US$22M | M7: Large pre-A round for a data-infra startup → immediate engineering build-out | N7: Data infra is literally the product — your strongest Data Engineer pitch; reach out to founders directly | O7: High | P7: Confirmed | Q7: KrASIA 'Deals in brief' 2026 | R7: v2 new | T7: Not started
A8: 4 | B8: OneByZero (OBZ) | C8: OneByZero | D8: AI Startups & Labs (Chinese-founded / SG-relocated) | E8: E | F8: SG-based enterprise AI deployment firm (founders' background to verify) | G8: ● | H8: ● | K8: ● | L8: Series A US$20M (Oct 2026, Jungle Ventures) | M8: Raised 5 Oct 2026 to expand APAC + enter Japan — hiring burst imminent | N8: Call this week: funding is 3 days old. Pitch forward-deployed engineers, data engineers, AI governance (enterprise rollout) | O8: High | P8: Confirmed | Q8: e27, 5 Oct 2026 | R8: v2 new | T8: Not started
A9: 5 | B9: Manus (Butterfly Effect) — now Meta | C9: 蝴蝶效应 Manus | D9: AI Startups & Labs (Chinese-founded / SG-relocated) | E9: B | F9: Founded in China (Xiao Hong); moved HQ to Singapore mid-2025; acquired by Meta (~US$2B); deal under Chinese regulatory review in 2026 | G9: ○ | I9: ● | K9: ● | L9: Agent startup inside Meta; ~US$100M ARR before deal | M9: Laid off China staff and closed China offices when relocating; post-acquisition integration + China review = uncertain but active SG engineering base | N9: Dual use: (1) client for agent / infra / agent-security engineers if Meta keeps scaling SG; (2) rich candidate pool if integration causes attrition. Verify current SG headcount first | O9: Medium-High | P9: Confirmed | Q9: SCMP 2025; Wikipedia 'Manus (AI agent)'; Rest of World 2026 | R9: v2 new | T9: Not started
A10: 6 | B10: Genspark (MainFunc) | C10: Genspark | D10: AI Startups & Labs (Chinese-founded / SG-relocated) | E10: B | F10: Founded by ex-Baidu Xiaodu CEO/CTO (Eric Jing, Kay Zhu); offices in Palo Alto, Singapore, Japan; majority-Chinese team per commentary | G10: ● | I10: ○ | K10: ● | L10: Unicorn; Tencent invested | M10: Super-agent product scaling fast; SG is one of three offices | N10: Mandarin-speaking founders — ideal fit for your pitch; ask whether SG will host engineering vs. GTM only | O10: Medium-High | P10: Likely | Q10: The Information (Tencent investment); Crunchbase; AI Supremacy | R10: v2 new | T10: Not started
A11: 7 | B11: Simular | C11: Simular | D11: AI Startups & Labs (Chinese-founded / SG-relocated) | E11: C | F11: Computer-use agent startup; co-founders ex-Google DeepMind (reported as Ang Li & Jiachen Yang — verify) | I11: ● | K11: ● | L11: Venture-backed startup | M11: Jun 2026: hiring its FIRST dedicated security engineer in Singapore (agent attack surface) | N11: Textbook AI Security role — bring agent-security / appsec candidates; first hire usually wants agency help | O11: Medium-High | P11: Confirmed | Q11: Seedtable job listing (Jun 2026) | R11: v2 new | T11: Not started
A12: 8 | B12: Envision Digital | C12: 远景智能 | D12: AI Startups & Labs (Chinese-founded / SG-relocated) | E12: B | F12: Envision Group (Zhang Lei) AIoT / energy-AI arm, global HQ in Singapore | G12: ● | H12: ● | K12: ● | L12: Large, US$210M raised (Sequoia China, GIC) | M12: AIoT/energy-AI platform; SG global HQ with China R&D | N12: Mandarin-speaking leadership + SG HQ — pitch data platform engineers and AI governance for energy/critical infra | O12: Medium-High | P12: Confirmed | Q12: DealStreetAsia; company website | R12: v2 new | T12: Not started
A13: 9 | B13: Tabcut | C13: Tabcut | D13: AI Startups & Labs (Chinese-founded / SG-relocated) | E13: B | F13: Hangzhou founders moved global HQ to Singapore after raising from Kamet Capital | G13: ● | K13: ● | L13: Early-stage, US$5.6M raised | M13: TikTok-Shop analytics/data SaaS — data engineering is the product | N13: Small team without in-house TA; offer contingent search for data/backend engineers | O13: Medium | P13: Confirmed | Q13: Bloomberg / BusinessWorld 2024 (relocation report) | R13: v2 new | T13: Not started
A14: 10 | B14: Agnes AI (SapiensAI) | C14: Agnes AI | D14: AI Startups & Labs (Chinese-founded / SG-relocated) | E14: C | F14: SG-based, founded 2025 by Bruce Yang; positioned in Chinese media as part of Chinese-founder wave in SG ('DeepSeek of SEA') | G14: ● | I14: ○ | K14: ● | L14: Series A (Feb 2026) | M14: Post-Series A team build in SG | N14: Freshly funded, small team — fast decisions; verify founder network (Chinese-media coverage suggests Mandarin-speaking leadership) | O14: Medium | P14: Likely | Q14: Dealroom; TMTPost | R14: v2 new | T14: Not started
A15: 11 | B15: Sapient Intelligence | C15: Sapient Intelligence | D15: AI Startups & Labs (Chinese-founded / SG-relocated) | E15: B | F15: SG-based AGI research startup (HRM model); Chinese founding team (founder reported as Guan Wang — verify) | G15: ○ | K15: ● | L15: Early-stage research lab | M15: Gained global attention for Hierarchical Reasoning Model (2025); research hiring in SG | N15: Pitch research engineers / ML infra; small team, founder-led hiring | O15: Medium | P15: To verify | Q15: Public reporting 2025; verify current funding/headcount | R15: v2 new | T15: Not started
A16: 12 | B16: Skywork AI (Kunlun Tech) | C16: 昆仑万维 天工 | D16: AI Startups & Labs (Chinese-founded / SG-relocated) | E16: B | F16: Kunlun Tech's overseas AI apps published via Skywork AI Pte. Ltd. (Singapore) | G16: ● | H16: ○ | K16: ● | L16: Listed parent (Shenzhen), overseas AI app arm | M16: Overseas AI products (agents, music, short drama) operated from SG entity | N16: Verify engineering vs. ops split in SG; pitch AI product engineers + overseas compliance | O16: Medium | P16: To verify | Q16: App-store publisher records; public reporting | R16: v2 new | T16: Not started
A17: 13 | B17: WIZ.AI | C17: WIZ.AI | D17: AI Startups & Labs (Chinese-founded / SG-relocated) | E17: B | F17: SG conversational/voice-AI startup with Chinese founding team (founder reported as Jennifer Zhang — verify) | G17: ● | H17: ○ | K17: ● | L17: Series B-stage | M17: Voice-agent demand rising across SEA banks/telcos | N17: Pitch speech/LLM engineers; small TA team | O17: Medium | P17: Likely | Q17: Company website; Tech in Asia | R17: v2 new | T17: Not started
A18: 14 | B18: AI Rudder | C18: AI Rudder | D18: AI Startups & Labs (Chinese-founded / SG-relocated) | E18: C | F18: SG voice-AI collections/CS platform; founding team background to verify | G18: ● | K18: ● | L18: Growth-stage | M18: Voice AI for fintech collections across SEA | N18: Verify leadership; fintech clients also give AI Risk angle | O18: Low-Medium | P18: To verify | Q18: Company website | R18: v2 new | T18: Not started
A19: 15 | B19: Hypotenuse AI | C19: Hypotenuse AI | D19: AI Startups & Labs (Chinese-founded / SG-relocated) | E19: C | F19: SG GenAI content startup (YC), Singaporean-Chinese founder | K19: ● | L19: Early-stage | M19: Lean product/engineering team | N19: Small but founder-led hiring; good for 1-2 senior SWE placements | O19: Low | P19: Likely | Q19: e27 (YC-backed SG AI startups) | R19: v2 new | T19: Not started
A20: 16 | B20: SmartMore | C20: 思谋科技 | D20: AI Startups & Labs (Chinese-founded / SG-relocated) | E20: A | F20: Shenzhen industrial-AI company; reported plan to expand into SEA starting with Singapore | G20: ● | K20: ● | L20: Large Chinese AI unicorn | M20: Reported SEA expansion plan (date unclear) | N20: Radar — check for SG entity / job posts | O20: Radar | P20: To verify | Q20: Public reporting (undated) | R20: v2 new | T20: Not started
A21: 17 | B21: MiniMax | C21: MiniMax | D21: Chinese Foundation-Model Firms Going Abroad | E21: A | F21: HK-listed; SG subsidiaries Subsup Pte. Ltd. & Nanonoble Pte. Ltd. in group structure | G21: ● | H21: ● | K21: ● | L21: Unicorn, HK IPO early 2026 | M21: SG entities now confirmed in filings; recruiting AI talent at NUS/NTU (May 2026) | N21: Upgrade to High: entities + campus hiring confirmed; ask about SG compliance/trust & safety team | O21: High | P21: Confirmed | Q21: HK IPO filings; HCAmag May 2026 | R21: v2 new | S21: v2: replaces v1 row — SG subsidiaries now confirmed in IPO filings; upgraded to High | T21: Not started
A22: 18 | B22: ByteDance Seed (AI research) — Singapore lab | C22: 字节跳动 Seed | D22: Chinese Foundation-Model Firms Going Abroad | E22: A | F22: Seed has labs in US, Singapore and China; separate hiring team from TikTok | G22: ● | I22: ● | K22: ● | L22: Mega-scale AI lab | M22: Bloomberg Feb 2026: ~100 open roles in AI division; SG is one of three lab locations | N22: Treat as a separate account from TikTok — pitch research engineers, LLM infra, AI safety / red-team | O22: High | P22: Confirmed | Q22: Bloomberg 19 Feb 2026 | R22: v2 new | T22: Not started
A23: 19 | B23: Zhipu AI (Z.ai) | C23: 智谱 | D23: Chinese Foundation-Model Firms Going Abroad | E23: A | F23: Chinese 'AI Tiger'; VP confirmed Singapore office; SG entity (Jingsheng Hengxing Technology Pte.) in IPO structure | G23: ● | H23: ● | K23: ● | L23: Unicorn, listed / IPO stage | M23: Overseas offices in SG, Middle East, UK, Malaysia; sovereign-AI partnerships across SEA | N23: Upgrade from radar: SG office confirmed. Overseas compliance = AI Governance need; plus solutions/data engineers for SEA deals | O23: Medium-High | P23: Confirmed | Q23: GITEX Asia remarks (AOL/Reuters); IPO filings | R23: v2 new | S23: v2: replaces v1 radar row — SG office confirmed | T23: Not started
A24: 20 | B24: Kuaishou — Symphony Tech (SG unit) | C24: 快手 新加坡 | D24: Chinese Foundation-Model Firms Going Abroad | E24: A | F24: Kuaishou launched AI-companion app FantaSay via its Singapore unit Symphony Tech | G24: ● | H24: ● | I24: ● | K24: ● | L24: Mega-scale parent | M24: Overseas AI-companion app run from SG; content-safety scrutiny (NSFW reports) | N24: AI Gov / trust & safety + AI engineers — strong governance pitch given content concerns | O24: Medium | P24: Confirmed | Q24: Yahoo Finance / Bloomberg | R24: v2.1 | S24: v2.1: new | T24: Not started
A25: 21 | B25: PixVerse (AIsphere) | C25: 爱诗科技 | D25: Chinese Foundation-Model Firms Going Abroad | E25: B | F25: AI-video company; reportedly HQ Singapore with research in Beijing (verify — low-reliability source) | G25: ● | H25: ● | K25: ● | L25: Unicorn-stage | M25: Global AI-video product | N25: If SG HQ confirmed: AI engineers + content governance | O25: Medium | P25: To verify | Q25: Wiki / company directories | R25: v2.1 | S25: v2.1: new | T25: Not started
A26: 22 | B26: Moonshot AI (Kimi) | C26: 月之暗面 | D26: Chinese Foundation-Model Firms Going Abroad | E26: A | F26: Beijing; scaled back overseas consumer apps (2024); preparing HK IPO | H26: ● | L26: Unicorn | M26: No SG team found | N26: Radar | O26: Radar | P26: To verify | Q26: Yicai 2024; Wikipedia | R26: v2.1 | S26: v2.1: split from grouped row 'Moonshot / StepFun / AI Tigers' | T26: Not started
A27: 23 | B27: StepFun | C27: 阶跃星辰 | D27: Chinese Foundation-Model Firms Going Abroad | E27: A | F27: Shanghai AI Tiger | H27: ● | L27: Unicorn | M27: No SG team found | N27: Radar | O27: Radar | P27: To verify | Q27: — | R27: v2.1 | S27: v2.1: split from grouped row 'Moonshot / StepFun / AI Tigers' | T27: Not started
A28: 24 | B28: Baichuan AI | C28: 百川智能 | D28: Chinese Foundation-Model Firms Going Abroad | E28: A | F28: Beijing AI Tiger (healthcare focus) | H28: ● | L28: Unicorn | M28: No SG team found | N28: Radar | O28: Radar | P28: To verify | Q28: — | R28: v2.1 | S28: v2.1: split from grouped row 'Moonshot / StepFun / AI Tigers' | T28: Not started
A29: 25 | B29: 01.AI | C29: 零一万物 | D29: Chinese Foundation-Model Firms Going Abroad | E29: A | F29: Kai-Fu Lee's AI company | H29: ● | L29: Unicorn | M29: No SG team found | N29: Radar | O29: Radar | P29: To verify | Q29: — | R29: v2.1 | S29: v2.1: split from grouped row 'Moonshot / StepFun / AI Tigers' | T29: Not started
A30: 26 | B30: ByteDance / TikTok Singapore | C30: 字节跳动 / TikTok | D30: Tech Giants (Regional / Global HQ) | E30: A | F30: Chinese HQ; SG is global/APAC hub | G30: ● | H30: ● | I30: ○ | K30: ○ | L30: Mega-scale, aggressively expanding | M30: 2,353 of its ~10,000 2026 campus-recruitment roles are AI-related; Singapore is its global/APAC hub, and global data-compliance scrutiny makes both AI governance and data engineering talent urgently needed | N30: One of the top priority targets: high headcount volume, fast expansion, and "global regulatory scrutiny" is itself the strongest AI Governance pitch angle | O30: High | P30: Likely | Q30: 36kr / industry reporting synthesis | R30: v1 | S30: v2: ByteDance Seed, Lark, BytePlus added as separate accounts; also merged duplicate row from v1 DE sheet | T30: Not started
A31: 27 | B31: Alibaba Group / Alibaba Cloud International (Singapore) | C31: 阿里巴巴 | D31: Tech Giants (Regional / Global HQ) | E31: A | F31: Chinese HQ / mainland parent | G31: ● | H31: ● | I31: ○ | K31: ○ | L31: Mega-scale | M31: Alibaba Cloud has been headquartered in Singapore since 2015; AI-related roles make up 60-80% of Alibaba International's hiring | N31: A core buyer of data engineering talent — build separate contacts across its three business lines (Cloud / Ant / Lazada) | O31: High | P31: Likely | Q31: Industry reporting synthesis | R31: v1 | S31: v2: Ant International and Lazada split into their own rows | T31: Not started
A32: 28 | B32: Tencent Singapore | C32: 腾讯 | D32: Tech Giants (Regional / Global HQ) | E32: A | F32: Chinese HQ / mainland parent | G32: ● | I32: ○ | K32: ○ | L32: Large, intense AI talent war | M32: Offering 150% pay raises + 35% bonuses to attract AI talent, implying ample hiring budget and fast decision-making | N32: The high-pay signal supports a "precision top-candidate sourcing" pitch | O32: High | P32: Confirmed | Q32: Tom's Hardware reporting | R32: v1 | T32: Not started
A33: 29 | B33: Xiaomi Singapore | C33: 小米 | D33: Tech Giants (Regional / Global HQ) | E33: A | F33: Chinese HQ / mainland parent | G33: ● | I33: ○ | K33: ○ | L33: Large | M33: Indeed lists 178+ Data Engineer-related roles, spanning from Engineer level up to VP of Technology / Big Data Architect | N33: High volume across all seniority levels — good fit for a standing-search agreement | O33: High | P33: Confirmed | Q33: Indeed job listing statistics | R33: v1 | T33: Not started
A34: 30 | B34: SHEIN Singapore | C34: 希音 | D34: Tech Giants (Regional / Global HQ) | E34: B | F34: Chinese-founded; registered HQ in Singapore | G34: ● | I34: ○ | K34: ○ | L34: Mega-scale, HQ-level | M34: Registered HQ in Singapore (Robinson Road); supply chain, ad spend, and dynamic pricing all drive heavy data engineering demand | N34: Decision-making power sits locally in Singapore — one of the highest-value accounts to cultivate | O34: High | P34: Confirmed | Q34: Company website / craft.co | R34: v1 | T34: Not started
A35: 31 | B35: Grab | C35: Grab | D35: Tech Giants (Regional / Global HQ) | E35: D | F35: Large China-origin engineering population; historically had a Beijing R&D centre (verify current tech leads) | G35: ● | I35: ○ | K35: ○ | M35: Singapore R&D centre, 5,001-10,000 employees, continuous large-scale hiring | N35: SEA's largest super-app, large and high-turnover data teams — a good candidate for a long-term, steady client relationship | O35: High | P35: Confirmed | Q35: Glassdoor / Grab careers page | R35: v1 | T35: Not started
A36: 32 | B36: Ant International (Alipay+, Antom, WorldFirst, ANEXT Bank) | C36: 蚂蚁国际 | D36: Tech Giants (Regional / Global HQ) | E36: A | F36: Global HQ in Singapore; Chinese leadership | G36: ● | H36: ● | I36: ● | J36: ● | K36: ● | L36: Mega-scale; 4 business lines | M36: AI-heavy: Alipay+ Cockpit AI-as-a-Service, AI SHIELD fraud detection; ANEXT is an MAS-licensed digital wholesale bank → MAS AI Risk Guidelines apply | N36: Best single account for AI Risk + AI Security (fraud/deepfake/KYC) + AI Gov; split from 'Alibaba' row in v1 — build separate contacts per business line | O36: High | P36: Confirmed | Q36: Ant International press releases; EDB | R36: v2 new | T36: Not started
A37: 33 | B37: Sea / Shopee / Garena / MariBank | C37: 冬海集团 | D37: Tech Giants (Regional / Global HQ) | E37: C | F37: Founder & CEO Forrest Li (Tianjin-born Singaporean); large China-origin engineering population | G37: ● | H37: ● | I37: ● | J37: ● | K37: ● | L37: Mega-scale | M37: AI CoE (Jul 2026); MariBank (MAS-licensed digital bank) now in scope of MAS AI Risk Guidelines | N37: Add MariBank as an AI Risk/Gov entry point; Shopee Trust & Safety for AI Security | O37: High | P37: Confirmed | Q37: Wikipedia (Forrest Li); company sites | R37: v2 new | S37: v2: replaces v1 row — added MariBank (AI Risk) and founder link | T37: Not started
A38: 34 | B38: Bigo Technology (JOYY) | C38: BIGO 欢聚 | D38: Tech Giants (Regional / Global HQ) | E38: B | F38: Chinese-founded, Singapore-headquartered live-streaming company; 6 R&D centres worldwide | G38: ● | I38: ● | K38: ● | L38: Large | M38: Live-streaming content moderation, recsys and ads all data/AI heavy | N38: Pitch data engineers + Trust & Safety / AI content-security engineers; Mandarin-speaking management | O38: Medium-High | P38: Confirmed | Q38: Company job-board profile | R38: v2 new | T38: Not started
A39: 35 | B39: Trip.com Group Singapore | C39: 携程 | D39: Tech Giants (Regional / Global HQ) | E39: B | F39: Chinese-founded; principal executive offices moved to Singapore | G39: ● | I39: ○ | K39: ○ | L39: Large, HQ relocating | M39: Principal executive offices have moved to Singapore; core team continues to expand | N39: HQ relocation means decisions are now local — a priority account | O39: Medium | P39: Confirmed | Q39: Wikipedia / company announcements | R39: v1 | T39: Not started
A40: 36 | B40: Huawei Singapore (Huawei Cloud / Huawei Intl) | C40: 华为新加坡 | D40: Tech Giants (Regional / Global HQ) | E40: A | F40: Chinese HQ; regional cloud + R&D | G40: ● | H40: ○ | I40: ● | K40: ● | L40: Mega-scale | M40: Huawei said it will increase SG campus recruitment in 2026; Huawei Cloud SG region | N40: Lateral roles in cloud/AI/security; long decision chain, Mandarin advantage | O40: Medium | P40: Confirmed | Q40: HCAmag / People Matters 2026 | R40: v2 new | T40: Not started
A41: 37 | B41: Lark (Feishu) International | C41: 飞书 Lark | D41: Tech Giants (Regional / Global HQ) | E41: A | F41: ByteDance made Singapore Lark's global HQ | H41: ● | I41: ● | K41: ● | L41: Large | M41: Enterprise SaaS selling into regulated industries → security/compliance engineering | N41: Pitch enterprise security, AI governance (data residency), backend SWE | O41: Medium | P41: Likely | Q41: KrASIA (older); 2025 SG job postings | R41: v2 new | T41: Not started
...

Sheet LinkedIn Search Plan
A1: LinkedIn Recruiter — Search Plan (one row per company; paste the strings into Recruiter's filters)
A2: How to use: in Recruiter, open the project → Search → Current company = column C, Location = Singapore, Job titles (Boolean) = column F for hiring managers, then column G for TA/HR. Save the 2-4 best people per company into the project. Column I opens a regular LinkedIn people search (pre-filtered to Singapore) for a quick check. Yellow columns are yours.
A4: # | B4: Company | C4: LinkedIn company filter (check exact page) | D4: Priority | E4: Project / Tag | F4: Hiring-manager titles (Boolean) | G4: TA / HR titles (Boolean) | H4: Founder string (startups) | I4: Quick LinkedIn search | J4: Template (1st msg) | K4: Language | L4: # people saved | M4: Names saved / notes | N4: Status
A5: 1 | B5: Plaud | C5: Plaud | D5: High | E5: BD-W1 High | F5: ("head of data" OR "data engineering manager" OR "director of data" OR "data platform" OR "head of data engineering" OR "chief data officer" OR CTO OR "VP engineering" OR "head of engineering" OR "engineering director" OR "engineering manager") | G5: ("talent acquisition" OR recruiter OR "recruitment" OR HRBP OR "head of HR" OR "people partner" OR "human resources") | H5: (founder OR "co-founder" OR CEO) | I5: Open search | J5: T2-CN | K5: CN (EN if local hire) | N5: Not started
A6: 2 | B6: MiroMind (Shanda Group) | C6: MiroMind | D6: High | E6: BD-W1 High | F6: (CISO OR "head of security" OR "security engineering" OR "AI security" OR "trust and safety" OR "head of cybersecurity" OR CTO OR "VP engineering" OR "head of engineering" OR "engineering director" OR "engineering manager") | G6: ("talent acquisition" OR recruiter OR "recruitment" OR HRBP OR "head of HR" OR "people partner" OR "human resources") | H6: (founder OR "co-founder" OR CEO) | I6: Open search | J6: T2-CN | K6: CN (EN if local hire) | N6: Not started
A7: 3 | B7: Ropedia | C7: Ropedia | D7: High | E7: BD-W1 High | F7: ("head of data" OR "data engineering manager" OR "director of data" OR "data platform" OR "head of data engineering" OR "chief data officer" OR CTO OR "VP engineering" OR "head of engineering" OR "engineering director" OR "engineering manager") | G7: ("talent acquisition" OR recruiter OR "recruitment" OR HRBP OR "head of HR" OR "people partner" OR "human resources") | H7: (founder OR "co-founder" OR CEO) | I7: Open search | J7: T2-EN | K7: EN (CN if Mandarin) | N7: Not started
A8: 4 | B8: OneByZero (OBZ) | C8: OneByZero | D8: High | E8: BD-W1 High | F8: ("head of data" OR "data engineering manager" OR "director of data" OR "data platform" OR "head of data engineering" OR "chief data officer" OR "AI governance" OR "responsible AI" OR "data governance" OR "head of compliance" OR "AI ethics" OR CTO) | G8: ("talent acquisition" OR recruiter OR "recruitment" OR HRBP OR "head of HR" OR "people partner" OR "human resources") | H8: (founder OR "co-founder" OR CEO) | I8: Open search | J8: T2-EN | K8: EN | N8: Not started
A9: 5 | B9: MiniMax | C9: MiniMax | D9: High | E9: BD-W1 High | F9: ("head of data" OR "data engineering manager" OR "director of data" OR "data platform" OR "head of data engineering" OR "chief data officer" OR "AI governance" OR "responsible AI" OR "data governance" OR "head of compliance" OR "AI ethics" OR CTO) | G9: ("talent acquisition" OR recruiter OR "recruitment" OR HRBP OR "head of HR" OR "people partner" OR "human resources") | I9: Open search | J9: T2-CN | K9: CN (EN if local hire) | N9: Not started
A10: 6 | B10: ByteDance Seed (AI research) — Singapore lab | C10: ByteDance Seed | D10: High | E10: BD-W1 High | F10: ("head of data" OR "data engineering manager" OR "director of data" OR "data platform" OR "head of data engineering" OR "chief data officer" OR CISO OR "head of security" OR "security engineering" OR "AI security" OR "trust and safety" OR "head of cybersecurity") | G10: ("talent acquisition" OR recruiter OR "recruitment" OR HRBP OR "head of HR" OR "people partner" OR "human resources") | I10: Open search | J10: T2-CN | K10: CN (EN if local hire) | N10: Not started
A11: 7 | B11: ByteDance / TikTok Singapore | C11: ByteDance OR TikTok | D11: High | E11: BD-W1 High | F11: ("head of data" OR "data engineering manager" OR "director of data" OR "data platform" OR "head of data engineering" OR "chief data officer" OR "AI governance" OR "responsible AI" OR "data governance" OR "head of compliance" OR "AI ethics") | G11: ("talent acquisition" OR recruiter OR "recruitment" OR HRBP OR "head of HR" OR "people partner" OR "human resources") | I11: Open search | J11: T1-CN | K11: CN (EN if local hire) | N11: Not started
A12: 8 | B12: Alibaba Group / Alibaba Cloud International (Singapore) | C12: Alibaba Group OR Alibaba Cloud International | D12: High | E12: BD-W1 High | F12: ("head of data" OR "data engineering manager" OR "director of data" OR "data platform" OR "head of data engineering" OR "chief data officer" OR "AI governance" OR "responsible AI" OR "data governance" OR "head of compliance" OR "AI ethics") | G12: ("talent acquisition" OR recruiter OR "recruitment" OR HRBP OR "head of HR" OR "people partner" OR "human resources") | I12: Open search | J12: T1-CN | K12: CN (EN if local hire) | N12: Not started
A13: 9 | B13: Tencent Singapore | C13: Tencent | D13: High | E13: BD-W1 High | F13: ("head of data" OR "data engineering manager" OR "director of data" OR "data platform" OR "head of data engineering" OR "chief data officer") | G13: ("talent acquisition" OR recruiter OR "recruitment" OR HRBP OR "head of HR" OR "people partner" OR "human resources") | I13: Open search | J13: T1-CN | K13: CN (EN if local hire) | N13: Not started
A14: 10 | B14: Xiaomi Singapore | C14: Xiaomi | D14: High | E14: BD-W1 High | F14: ("head of data" OR "data engineering manager" OR "director of data" OR "data platform" OR "head of data engineering" OR "chief data officer") | G14: ("talent acquisition" OR recruiter OR "recruitment" OR HRBP OR "head of HR" OR "people partner" OR "human resources") | I14: Open search | J14: T1-CN | K14: CN (EN if local hire) | N14: Not started
A15: 11 | B15: SHEIN Singapore | C15: SHEIN | D15: High | E15: BD-W1 High | F15: ("head of data" OR "data engineering manager" OR "director of data" OR "data platform" OR "head of data engineering" OR "chief data officer") | G15: ("talent acquisition" OR recruiter OR "recruitment" OR HRBP OR "head of HR" OR "people partner" OR "human resources") | I15: Open search | J15: T1-CN | K15: CN (EN if local hire) | N15: Not started
A16: 12 | B16: Grab | C16: Grab | D16: High | E16: BD-W1 High | F16: ("head of data" OR "data engineering manager" OR "director of data" OR "data platform" OR "head of data engineering" OR "chief data officer") | G16: ("talent acquisition" OR recruiter OR "recruitment" OR HRBP OR "head of HR" OR "people partner" OR "human resources") | I16: Open search | J16: T1-EN | K16: EN | N16: Not started
A17: 13 | B17: Ant International (Alipay+, Antom, WorldFirst, ANEXT Bank) | C17: Ant International | D17: High | E17: BD-W1 High | F17: ("head of data" OR "data engineering manager" OR "director of data" OR "data platform" OR "head of data engineering" OR "chief data officer" OR "AI governance" OR "responsible AI" OR "data governance" OR "head of compliance" OR "AI ethics" OR CISO) | G17: ("talent acquisition" OR recruiter OR "recruitment" OR HRBP OR "head of HR" OR "people partner" OR "human resources") | I17: Open search | J17: T1-CN | K17: CN (EN if local hire) | N17: Not started
A18: 14 | B18: Sea / Shopee / Garena / MariBank | C18: Sea OR Shopee OR Garena OR MariBank | D18: High | E18: BD-W1 High | F18: ("head of data" OR "data engineering manager" OR "director of data" OR "data platform" OR "head of data engineering" OR "chief data officer" OR "AI governance" OR "responsible AI" OR "data governance" OR "head of compliance" OR "AI ethics" OR CISO) | G18: ("talent acquisition" OR recruiter OR "recruitment" OR HRBP OR "head of HR" OR "people partner" OR "human resources") | I18: Open search | J18: T1-EN | K18: EN (CN if Mandarin) | N18: Not started
A19: 15 | B19: ADVANCE.AI / Atome (Advance Intelligence Group) | C19: ADVANCE.AI OR Atome | D19: High | E19: BD-W1 High | F19: ("head of data" OR "data engineering manager" OR "director of data" OR "data platform" OR "head of data engineering" OR "chief data officer" OR "AI governance" OR "responsible AI" OR "data governance" OR "head of compliance" OR "AI ethics" OR CISO) | G19: ("talent acquisition" OR recruiter OR "recruitment" OR HRBP OR "head of HR" OR "people partner" OR "human resources") | I19: Open search | J19: T3-CN | K19: CN (EN if local hire) | N19: Not started
A20: 16 | B20: Moomoo (Futu) Singapore | C20: Moomoo | D20: High | E20: BD-W1 High | F20: ("head of data" OR "data engineering manager" OR "director of data" OR "data platform" OR "head of data engineering" OR "chief data officer" OR "AI governance" OR "responsible AI" OR "data governance" OR "head of compliance" OR "AI ethics" OR CISO) | G20: ("talent acquisition" OR recruiter OR "recruitment" OR HRBP OR "head of HR" OR "people partner" OR "human resources") | I20: Open search | J20: T3-CN | K20: CN (EN if local hire) | N20: Not started
A21: 17 | B21: Tiger Brokers (UP Fintech) Singapore | C21: Tiger Brokers | D21: High | E21: BD-W1 High | F21: ("head of data" OR "data engineering manager" OR "director of data" OR "data platform" OR "head of data engineering" OR "chief data officer" OR "AI governance" OR "responsible AI" OR "data governance" OR "head of compliance" OR "AI ethics" OR CISO) | G21: ("talent acquisition" OR recruiter OR "recruitment" OR HRBP OR "head of HR" OR "people partner" OR "human resources") | I21: Open search | J21: T3-CN | K21: CN (EN if local hire) | N21: Not started
A22: 18 | B22: Bullet | C22: Bullet | D22: High | E22: BD-W1 High | F22: ("head of data" OR "data engineering manager" OR "director of data" OR "data platform" OR "head of data engineering" OR "chief data officer") | G22: ("talent acquisition" OR recruiter OR "recruitment" OR HRBP OR "head of HR" OR "people partner" OR "human resources") | H22: (founder OR "co-founder" OR CEO) | I22: Open search | J22: T1-EN | K22: EN | N22: Not started
A23: 19 | B23: HoYoverse (miHoYo) Singapore | C23: HoYoverse | D23: High | E23: BD-W1 High | F23: ("head of data" OR "data engineering manager" OR "director of data" OR "data platform" OR "head of data engineering" OR "chief data officer") | G23: ("talent acquisition" OR recruiter OR "recruitment" OR HRBP OR "head of HR" OR "people partner" OR "human resources") | I23: Open search | J23: T1-CN | K23: CN (EN if local hire) | N23: Not started
A24: 20 | B24: Huatai Securities (Singapore) | C24: Huatai Securities | D24: High | E24: BD-W1 High | F24: ("head of data" OR "data engineering manager" OR "director of data" OR "data platform" OR "head of data engineering" OR "chief data officer" OR "AI governance" OR "responsible AI" OR "data governance" OR "head of compliance" OR "AI ethics" OR "model risk") | G24: ("talent acquisition" OR recruiter OR "recruitment" OR HRBP OR "head of HR" OR "people partner" OR "human resources") | I24: Open search | J24: T3-CN | K24: CN (EN if local hire) | N24: Not started
A25: 21 | B25: High-Flyer Quant (幻方量化, DeepSeek's parent) [verify SG team first] | C25: High-Flyer Quant | D25: High | E25: BD-W1 High | F25: ("head of data" OR "data engineering manager" OR "director of data" OR "data platform" OR "head of data engineering" OR "chief data officer") | G25: ("talent acquisition" OR recruiter OR "recruitment" OR HRBP OR "head of HR" OR "people partner" OR "human resources") | I25: Open search | J25: T5-CN | K25: CN (EN if local hire) | N25: Not started
A26: 22 | B26: MS Capital (Meridian & Saturn Capital) | C26: MS Capital | D26: High | E26: BD-W1 High | F26: ("head of data" OR "data engineering manager" OR "director of data" OR "data platform" OR "head of data engineering" OR "chief data officer") | G26: ("talent acquisition" OR recruiter OR "recruitment" OR HRBP OR "head of HR" OR "people partner" OR "human resources") | I26: Open search | J26: T5-CN | K26: CN (EN if local hire) | N26: Not started
A27: 23 | B27: Qube Research & Technologies | C27: Qube Research & Technologies | D27: High | E27: BD-W1 High | F27: ("head of data" OR "data engineering manager" OR "director of data" OR "data platform" OR "head of data engineering" OR "chief data officer") | G27: ("talent acquisition" OR recruiter OR "recruitment" OR HRBP OR "head of HR" OR "people partner" OR "human resources") | I27: Open search | J27: T5-EN | K27: EN | N27: Not started
A28: 24 | B28: Lingjun Investment | C28: Lingjun Investment | D28: High | E28: BD-W1 High | F28: ("head of data" OR "data engineering manager" OR "director of data" OR "data platform" OR "head of data engineering" OR "chief data officer" OR "model risk" OR "head of risk" OR "chief risk officer" OR "risk analytics" OR "fraud" OR "model validation") | G28: ("talent acquisition" OR recruiter OR "recruitment" OR HRBP OR "head of HR" OR "people partner" OR "human resources") | I28: Open search | J28: T5-CN | K28: CN (EN if local hire) | N28: Not started
A29: 25 | B29: EY Singapore | C29: EY | D29: High | E29: BD-W1 High | F29: ("AI governance" OR "responsible AI" OR "data governance" OR "chief data officer" OR "head of compliance" OR "AI ethics" OR "model risk" OR "head of risk" OR "chief risk officer" OR "risk analytics" OR "fraud" OR "model validation") | G29: ("talent acquisition" OR recruiter OR "recruitment" OR HRBP OR "head of HR" OR "people partner" OR "human resources") | I29: Open search | J29: T1-EN | K29: EN | N29: Not started
A30: 26 | B30: PwC Singapore | C30: PwC | D30: High | E30: BD-W1 High | F30: ("AI governance" OR "responsible AI" OR "data governance" OR "chief data officer" OR "head of compliance" OR "AI ethics") | G30: ("talent acquisition" OR recruiter OR "recruitment" OR HRBP OR "head of HR" OR "people partner" OR "human resources") | I30: Open search | J30: T1-EN | K30: EN | N30: Not started
A31: 27 | B31: DBS Bank | C31: DBS Bank | D31: High | E31: BD-W1 High | F31: ("AI governance" OR "responsible AI" OR "data governance" OR "chief data officer" OR "head of compliance" OR "AI ethics" OR "model risk" OR "head of risk" OR "chief risk officer" OR "risk analytics" OR "fraud" OR "model validation") | G31: ("talent acquisition" OR recruiter OR "recruitment" OR HRBP OR "head of HR" OR "people partner" OR "human resources") | I31: Open search | J31: T3-EN | K31: EN | N31: Not started
A32: 28 | B32: UOB | C32: UOB | D32: High | E32: BD-W1 High | F32: ("AI governance" OR "responsible AI" OR "data governance" OR "chief data officer" OR "head of compliance" OR "AI ethics" OR "model risk" OR "head of risk" OR "chief risk officer" OR "risk analytics" OR "fraud" OR "model validation") | G32: ("talent acquisition" OR recruiter OR "recruitment" OR HRBP OR "head of HR" OR "people partner" OR "human resources") | I32: Open search | J32: T3-EN | K32: EN | N32: Not started
A33: 29 | B33: Prudential (PACS) | C33: Prudential | D33: High | E33: BD-W1 High | F33: ("AI governance" OR "responsible AI" OR "data governance" OR "chief data officer" OR "head of compliance" OR "AI ethics") | G33: ("talent acquisition" OR recruiter OR "recruitment" OR HRBP OR "head of HR" OR "people partner" OR "human resources") | I33: Open search | J33: T3-EN | K33: EN | N33: Not started
A34: 30 | B34: Manus (Butterfly Effect) — now Meta | C34: Manus | D34: Medium-High | E34: BD-W1 High | F34: (CISO OR "head of security" OR "security engineering" OR "AI security" OR "trust and safety" OR "head of cybersecurity" OR CTO OR "VP engineering" OR "head of engineering" OR "engineering director" OR "engineering manager") | G34: ("talent acquisition" OR recruiter OR "recruitment" OR HRBP OR "head of HR" OR "people partner" OR "human resources") | H34: (founder OR "co-founder" OR CEO) | I34: Open search | J34: T2-CN | K34: CN (EN if local hire) | N34: Not started
A35: 31 | B35: Genspark (MainFunc) | C35: Genspark | D35: Medium-High | E35: BD-W1 High | F35: ("head of data" OR "data engineering manager" OR "director of data" OR "data platform" OR "head of data engineering" OR "chief data officer" OR CTO OR "VP engineering" OR "head of engineering" OR "engineering director" OR "engineering manager") | G35: ("talent acquisition" OR recruiter OR "recruitment" OR HRBP OR "head of HR" OR "people partner" OR "human resources") | H35: (founder OR "co-founder" OR CEO) | I35: Open search | J35: T2-CN | K35: CN (EN if local hire) | N35: Not started
A36: 32 | B36: Simular | C36: Simular | D36: Medium-High | E36: BD-W1 High | F36: (CISO OR "head of security" OR "security engineering" OR "AI security" OR "trust and safety" OR "head of cybersecurity" OR CTO OR "VP engineering" OR "head of engineering" OR "engineering director" OR "engineering manager") | G36: ("talent acquisition" OR recruiter OR "recruitment" OR HRBP OR "head of HR" OR "people partner" OR "human resources") | H36: (founder OR "co-founder" OR CEO) | I36: Open search | J36: T2-EN | K36: EN (CN if Mandarin) | N36: Not started
A37: 33 | B37: Envision Digital | C37: Envision Digital | D37: Medium-High | E37: BD-W1 High | F37: ("head of data" OR "data engineering manager" OR "director of data" OR "data platform" OR "head of data engineering" OR "chief data officer" OR "AI governance" OR "responsible AI" OR "data governance" OR "head of compliance" OR "AI ethics" OR CTO) | G37: ("talent acquisition" OR recruiter OR "recruitment" OR HRBP OR "head of HR" OR "people partner" OR "human resources") | H37: (founder OR "co-founder" OR CEO) | I37: Open search | J37: T2-CN | K37: CN (EN if local hire) | N37: Not started
A38: 34 | B38: Zhipu AI (Z.ai) | C38: Zhipu AI | D38: Medium-High | E38: BD-W1 High | F38: ("head of data" OR "data engineering manager" OR "director of data" OR "data platform" OR "head of data engineering" OR "chief data officer" OR "AI governance" OR "responsible AI" OR "data governance" OR "head of compliance" OR "AI ethics" OR CTO) | G38: ("talent acquisition" OR recruiter OR "recruitment" OR HRBP OR "head of HR" OR "people partner" OR "human resources") | I38: Open search | J38: T2-CN | K38: CN (EN if local hire) | N38: Not started
A39: 35 | B39: Bigo Technology (JOYY) | C39: Bigo Technology | D39: Medium-High | E39: BD-W1 High | F39: ("head of data" OR "data engineering manager" OR "director of data" OR "data platform" OR "head of data engineering" OR "chief data officer" OR CISO OR "head of security" OR "security engineering" OR "AI security" OR "trust and safety" OR "head of cybersecurity") | G39: ("talent acquisition" OR recruiter OR "recruitment" OR HRBP OR "head of HR" OR "people partner" OR "human resources") | I39: Open search | J39: T1-CN | K39: CN (EN if local hire) | N39: Not started
A40: 36 | B40: FinVolution Group | C40: FinVolution Group | D40: Medium-High | E40: BD-W1 High | F40: ("head of data" OR "data engineering manager" OR "director of data" OR "data platform" OR "head of data engineering" OR "chief data officer" OR "model risk" OR "head of risk" OR "chief risk officer" OR "risk analytics" OR "fraud" OR "model validation") | G40: ("talent acquisition" OR recruiter OR "recruitment" OR HRBP OR "head of HR" OR "people partner" OR "human resources") | I40: Open search | J40: T3-CN | K40: CN (EN if local hire) | N40: Not started
A41: 37 | B41: SUNRATE | C41: SUNRATE | D41: Medium-High | E41: BD-W1 High | F41: ("head of data" OR "data engineering manager" OR "director of data" OR "data platform" OR "head of data engineering" OR "chief data officer" OR "AI governance" OR "responsible AI" OR "data governance" OR "head of compliance" OR "AI ethics" OR "model risk") | G41: ("talent acquisition" OR recruiter OR "recruitment" OR HRBP OR "head of HR" OR "people partner" OR "human resources") | I41: Open search | J41: T3-EN | K41: EN (CN if Mandarin) | N41: Not started
...

Sheet InMail Templates
A1: InMail Templates — save each one in Recruiter (Settings → Templates, or the 'Templates' menu when composing)
A2: {firstName} / {company} / {senderFirstName}: replace with Recruiter's own variables via the 'Insert' menu in the template editor. [Square brackets] = edit per message (signal, role, X). LinkedIn limits: subject ≤200 characters, body ≤1,900; columns F-G check this.
A4: ID | B4: Use for | C4: Lang | D4: Subject | E4: Body | F4: Subject chars | G4: Body chars
A5: T1-CN | B5: General — hiring manager | C5: CN | D5: 新加坡{company}技术团队招聘 — 一位工程师出身的猎头 | E5: {firstName}您好， 我是{senderFirstName}，在新加坡做技术猎头，之前做了[X]年软件工程师，现在专注 Data Engineering、AI Governance、AI Security / Risk 和软件工程方向。 注意到{company}最近[具体信号]。中资企业在新加坡招技术人才，常见难点是总部不太了解本地薪酬行情，合适的候选人又大多不主动看机会。我可以用中文和总部沟通，用英文对接本地候选人，并先做一轮技术筛选。 您这边近期在新加坡有没有比较难招的技术岗位？方便的话约15分钟聊聊，我也可以先分享这几个方向的新加坡薪酬行情供您参考。 谢谢！ {senderFirstName} | F5: =LEN(D5) -> 31 | G5: =LEN(E5) -> 311
A6: T1-EN | B6: General — hiring manager | C6: EN | D6: Hard-to-fill tech roles at {company} Singapore? | E6: Hi {firstName}, I'm {senderFirstName}, a Singapore tech recruiter and former software engineer ([X] years). I focus on data engineering, AI governance, AI security / risk and software engineering. I noticed {company} recently [signal]. The strongest people for these roles rarely apply to job ads, so I reach them directly and screen technically before anyone reaches your team. Is there a role on your Singapore roadmap that's proving hard to fill? Happy to share current salary benchmarks over a 15-minute call. Best, {senderFirstName} | F6: =LEN(D6) -> 47 | G6: =LEN(E6) -> 541
A7: T2-CN | B7: Funded / scaling AI startup — founder or CTO | C7: CN | D7: 恭喜{company}[融资/新总部] — 新加坡团队扩张 | E7: {firstName}您好，恭喜{company}[完成X轮融资 / 新加坡总部开业]！ 这个阶段通常是招人最快、但招聘体系还没搭起来的时候。我是工程师出身的猎头，专注 AI / Agent 工程、数据工程和 AI 安全方向，可以先替你们做技术筛选，节省团队的面试时间。 如果[岗位]在计划里，我可以在[X]个工作日内先发2-3份匿名候选人简介，合不合适您来判断，不合适不收费。方便聊15分钟吗？ {senderFirstName} | F7: =LEN(D7) -> 29 | G7: =LEN(E7) -> 219
A8: T2-EN | B8: Funded / scaling AI startup — founder or CTO | C8: EN | D8: Congrats on [milestone] — scaling {company} in Singapore | E8: Hi {firstName}, congratulations on [milestone]! This is usually when hiring moves fastest but internal recruiting isn't in place yet. I'm an ex-engineer recruiter focused on AI / agent engineering, data engineering and AI security, so I screen technically before anyone reaches your team. If [role] is on your plan, I can send 2-3 anonymised profiles within [X] working days. You judge the fit, and there's no fee unless you hire. Open to a 15-minute call? {senderFirstName} | F8: =LEN(D8) -> 56 | G8: =LEN(E8) -> 477
A9: T3-CN | B9: MAS-regulated FI — AI governance / AI risk | C9: CN | D9: MAS《AI风险管理指引》— {company}新加坡的人才准备 | E9: {firstName}您好， MAS 于10月7日发布了《AI风险管理指引》，适用于所有持牌金融机构，过渡期约12个月，涵盖AI使用清单、风险评估、模型验证和治理责任。 既懂ML模型又懂监管的人在新加坡非常稀缺，接下来一年银行、券商和保险都会集中招聘。我专注 AI Governance / AI Risk / 数据方向的招聘，可以先给您一页简要说明：新规对人员配置的影响和市场薪酬，方便您向总部汇报。 方便约个时间聊聊吗？ {senderFirstName} | F9: =LEN(D9) -> 32 | G9: =LEN(E9) -> 234
A10: T3-EN | B10: MAS-regulated FI — AI governance / AI risk | C10: EN | D10: MAS AI Risk Guidelines — staffing at {company} | E10: Hi {firstName}, MAS issued its AI Risk Management Guidelines on 7 October, with a transition period of roughly 12 months covering AI inventory, risk assessment, model validation and accountability. People who understand both ML models and regulation are scarce in Singapore, and most FIs will be hiring for these roles over the next year. I specialise in AI governance, AI risk and data hiring. I'd be glad to share a one-page brief on what the guidelines mean for headcount, plus current market rates. Would a short call be useful? {senderFirstName} | F10: =LEN(D10) -> 46 | G10: =LEN(E10) -> 554
A11: T4-CN | B11: AI security — CISO / security lead | C11: CN | D11: AI / Agent 安全人才 — 新加坡 | E11: {firstName}您好， AI Agent 带来的攻击面（prompt injection、工具调用权限、数据外泄）和传统应用安全很不一样，真正做过 LLM / Agent 安全的人在新加坡很少。 我是工程师出身的猎头，专门在做 AI Security 这个细分方向。如果{company}在新加坡有相关岗位，或者在规划这块能力，我可以先发几份匿名候选人简介给您参考。 方便的话回复一下就好。 {senderFirstName} | F11: =LEN(D11) -> 21 | G11: =LEN(E11) -> 220
A12: T4-EN | B12: AI security — CISO / security lead | C12: EN | D12: AI / agent security talent in Singapore | E12: Hi {firstName}, Securing AI agents (prompt injection, tool permissions, data exfiltration) is a different skill set from traditional appsec, and few people in Singapore have done it hands-on. As an ex-engineer, I focus on this niche. If {company} is hiring for it in Singapore, or planning to build the capability, I can send a few anonymised profiles for reference. Just reply if useful. {senderFirstName} | F12: =LEN(D12) -> 39 | G12: =LEN(E12) -> 410
A13: T5-CN | B13: Quant / trading — head of tech or data | C13: CN | D13: 新加坡量化数据工程人才 | E13: {firstName}您好， 我是{senderFirstName}，在新加坡做技术猎头，工程师出身，专注量化方向的数据工程和基础设施岗位（行情数据、另类数据、研究平台）。 看到{company}[在新加坡设办公室 / 扩团队]。这类候选人基本不主动看机会，我主要靠定向挖掘，能找到在新加坡本地、做过量化数据基础设施的人。 如果近期有相关岗位，我可以先发2-3份匿名简介，您看是否对口。 {senderFirstName} | F13: =LEN(D13) -> 11 | G13: =LEN(E13) -> 215
A14: T5-EN | B14: Quant / trading — head of tech or data | C14: EN | D14: Quant data engineering talent — Singapore | E14: Hi {firstName}, I'm {senderFirstName}, an ex-engineer tech recruiter in Singapore focused on quant data engineering and infrastructure (market data, alt-data, research platforms). These candidates are almost never on the market, so I find them through targeted headhunting, with a focus on people already in Singapore. If {company} has a data or infra role open, I can send 2-3 anonymised profiles so you can judge the fit. {senderFirstName} | F14: =LEN(D14) -> 41 | G14: =LEN(E14) -> 445
A15: T6-CN | B15: TA / HR — partnership | C15: CN | D15: 新加坡技术招聘合作 — {company} | E15: {firstName}您好， 我是{senderFirstName}，新加坡技术猎头，工程师出身，专注 AI / 数据 / AI 安全与风控方向。 了解到{company}在新加坡[扩张/招聘]。很多团队会把这类难招的技术岗位交给专精的外部顾问补充，我可以先接1-2个最难的岗位，用实际结果来证明价值。 想问一下贵司目前和猎头合作的流程（供应商名单或条款）是怎样的？方便的话约15分钟聊聊。 {senderFirstName} | F15: =LEN(D15) -> 21 | G15: =LEN(E15) -> 217
A16: T6-EN | B16: TA / HR — partnership | C16: EN | D16: Supporting {company}'s tech hiring in Singapore | E16: Hi {firstName}, I'm {senderFirstName}, an ex-engineer tech recruiter in Singapore focused on AI, data, AI security and AI risk roles. I understand {company} is [growing / hiring] in Singapore. Many TA teams bring in a specialist for their hardest technical roles, and I'd be happy to start with one or two of yours and prove value on results. Could you share how you work with agencies (PSL, terms)? Happy to set up a quick 15-minute call. {senderFirstName} | F16: =LEN(D16) -> 47 | G16: =LEN(E16) -> 461
... A20: F2-EN | B20: Follow-up #2 (day 14) — last | C20: EN | D20: Closing the loop | E20: Hi {firstName}, closing the loop here. If {company} ever needs help with AI or data hiring in Singapore, I'm happy to help, and I'll keep you posted on market moves in this space. All the best! {senderFirstName} | F20: =LEN(D20) -> 16 | G20: =LEN(E20) -> 212

Sheet Summary
A1: Summary — counts update automatically from 'Master Target List'
A3: Category | B3: High | C3: Medium-High | D3: Medium | E3: Low-Medium | F3: Low | G3: Radar | H3: Total | I3: of which added in v2/v2.1
A4: AI Startups & Labs (Chinese-founded / SG-relocated) | B4: =COUNTIFS('Master Target List'!$D$5:$D$226,$A4,'Master Target List'!$O$5:$O$226,"High") -> 4 | C4: =COUNTIFS('Master Target List'!$D$5:$D$226,$A4,'Master Target List'!$O$5:$O$226,"Medium-High") -> 4 | D4: =COUNTIFS('Master Target List'!$D$5:$D$226,$A4,'Master Target List'!$O$5:$O$226,"Medium") -> 5 | E4: =COUNTIFS('Master Target List'!$D$5:$D$226,$A4,'Master Target List'!$O$5:$O$226,"Low-Medium") -> 1 | F4: =COUNTIFS('Master Target List'!$D$5:$D$226,$A4,'Master Target List'!$O$5:$O$226,"Low") -> 1 | G4: =COUNTIFS('Master Target List'!$D$5:$D$226,$A4,'Master Target List'!$O$5:$O$226,"Radar") -> 1 | H4: =SUM(B4:G4) -> 16 | I4: =COUNTIFS('Master Target List'!$D$5:$D$226,$A4,'Master Target List'!$R$5:$R$226,"<>v1") -> 16
A5: Chinese Foundation-Model Firms Going Abroad | B5: =COUNTIFS('Master Target List'!$D$5:$D$226,$A5,'Master Target List'!$O$5:$O$226,"High") -> 2 | C5: =COUNTIFS('Master Target List'!$D$5:$D$226,$A5,'Master Target List'!$O$5:$O$226,"Medium-High") -> 1 | D5: =COUNTIFS('Master Target List'!$D$5:$D$226,$A5,'Master Target List'!$O$5:$O$226,"Medium") -> 2 | E5: =COUNTIFS('Master Target List'!$D$5:$D$226,$A5,'Master Target List'!$O$5:$O$226,"Low-Medium") -> 0 | F5: =COUNTIFS('Master Target List'!$D$5:$D$226,$A5,'Master Target List'!$O$5:$O$226,"Low") -> 0 | G5: =COUNTIFS('Master Target List'!$D$5:$D$226,$A5,'Master Target List'!$O$5:$O$226,"Radar") -> 4 | H5: =SUM(B5:G5) -> 9 | I5: =COUNTIFS('Master Target List'!$D$5:$D$226,$A5,'Master Target List'!$R$5:$R$226,"<>v1") -> 9
A6: Tech Giants (Regional / Global HQ) | B6: =COUNTIFS('Master Target List'!$D$5:$D$226,$A6,'Master Target List'!$O$5:$O$226,"High") -> 8 | C6: =COUNTIFS('Master Target List'!$D$5:$D$226,$A6,'Master Target List'!$O$5:$O$226,"Medium-High") -> 1 | D6: =COUNTIFS('Master Target List'!$D$5:$D$226,$A6,'Master Target List'!$O$5:$O$226,"Medium") -> 8 | E6: =COUNTIFS('Master Target List'!$D$5:$D$226,$A6,'Master Target List'!$O$5:$O$226,"Low-Medium") -> 0 | F6: =COUNTIFS('Master Target List'!$D$5:$D$226,$A6,'Master Target List'!$O$5:$O$226,"Low") -> 2 | G6: =COUNTIFS('Master Target List'!$D$5:$D$226,$A6,'Master Target List'!$O$5:$O$226,"Radar") -> 4 | H6: =SUM(B6:G6) -> 23 | I6: =COUNTIFS('Master Target List'!$D$5:$D$226,$A6,'Master Target List'!$R$5:$R$226,"<>v1") -> 16
A7: Fintech / Payments / Digital Banks | B7: =COUNTIFS('Master Target List'!$D$5:$D$226,$A7,'Master Target List'!$O$5:$O$226,"High") -> 1 | C7: =COUNTIFS('Master Target List'!$D$5:$D$226,$A7,'Master Target List'!$O$5:$O$226,"Medium-High") -> 2 | D7: =COUNTIFS('Master Target List'!$D$5:$D$226,$A7,'Master Target List'!$O$5:$O$226,"Medium") -> 9 | E7: =COUNTIFS('Master Target List'!$D$5:$D$226,$A7,'Master Target List'!$O$5:$O$226,"Low-Medium") -> 5 | F7: =COUNTIFS('Master Target List'!$D$5:$D$226,$A7,'Master Target List'!$O$5:$O$226,"Low") -> 0 | G7: =COUNTIFS('Master Target List'!$D$5:$D$226,$A7,'Master Target List'!$O$5:$O$226,"Radar") -> 4 | H7: =SUM(B7:G7) -> 21 | I7: =COUNTIFS('Master Target List'!$D$5:$D$226,$A7,'Master Target List'!$R$5:$R$226,"<>v1") -> 18
A8: Online Brokerages / Wealth Platforms | B8: =COUNTIFS('Master Target List'!$D$5:$D$226,$A8,'Master Target List'!$O$5:$O$226,"High") -> 2 | C8: =COUNTIFS('Master Target List'!$D$5:$D$226,$A8,'Master Target List'!$O$5:$O$226,"Medium-High") -> 0 | D8: =COUNTIFS('Master Target List'!$D$5:$D$226,$A8,'Master Target List'!$O$5:$O$226,"Medium") -> 2 | E8: =COUNTIFS('Master Target List'!$D$5:$D$226,$A8,'Master Target List'!$O$5:$O$226,"Low-Medium") -> 0 | F8: =COUNTIFS('Master Target List'!$D$5:$D$226,$A8,'Master Target List'!$O$5:$O$226,"Low") -> 0 | G8: =COUNTIFS('Master Target List'!$D$5:$D$226,$A8,'Master Target List'!$O$5:$O$226,"Radar") -> 0 | H8: =SUM(B8:G8) -> 4 | I8: =COUNTIFS('Master Target List'!$D$5:$D$226,$A8,'Master Target List'!$R$5:$R$226,"<>v1") -> 4
A9: Crypto / Web3 | B9: =COUNTIFS('Master Target List'!$D$5:$D$226,$A9,'Master Target List'!$O$5:$O$226,"High") -> 1 | C9: =COUNTIFS('Master Target List'!$D$5:$D$226,$A9,'Master Target List'!$O$5:$O$226,"Medium-High") -> 2 | D9: =COUNTIFS('Master Target List'!$D$5:$D$226,$A9,'Master Target List'!$O$5:$O$226,"Medium") -> 7 | E9: =COUNTIFS('Master Target List'!$D$5:$D$226,$A9,'Master Target List'!$O$5:$O$226,"Low-Medium") -> 3 | F9: =COUNTIFS('Master Target List'!$D$5:$D$226,$A9,'Master Target List'!$O$5:$O$226,"Low") -> 2 | G9: =COUNTIFS('Master Target List'!$D$5:$D$226,$A9,'Master Target List'!$O$5:$O$226,"Radar") -> 0 | H9: =SUM(B9:G9) -> 15 | I9: =COUNTIFS('Master Target List'!$D$5:$D$226,$A9,'Master Target List'!$R$5:$R$226,"<>v1") -> 8
A10: Robotics / Autonomous Driving | B10: =COUNTIFS('Master Target List'!$D$5:$D$226,$A10,'Master Target List'!$O$5:$O$226,"High") -> 0 | C10: =COUNTIFS('Master Target List'!$D$5:$D$226,$A10,'Master Target List'!$O$5:$O$226,"Medium-High") -> 0 | D10: =COUNTIFS('Master Target List'!$D$5:$D$226,$A10,'Master Target List'!$O$5:$O$226,"Medium") -> 3 | E10: =COUNTIFS('Master Target List'!$D$5:$D$226,$A10,'Master Target List'!$O$5:$O$226,"Low-Medium") -> 2 | F10: =COUNTIFS('Master Target List'!$D$5:$D$226,$A10,'Master Target List'!$O$5:$O$226,"Low") -> 4 | G10: =COUNTIFS('Master Target List'!$D$5:$D$226,$A10,'Master Target List'!$O$5:$O$226,"Radar") -> 2 | H10: =SUM(B10:G10) -> 11 | I10: =COUNTIFS('Master Target List'!$D$5:$D$226,$A10,'Master Target List'!$R$5:$R$226,"<>v1") -> 11
